Workbook

Sheet Raw_Data
A1: Medical Equipment Firm - Raw Data | Jan 2025 to May 2026
A3: Month | B3: Product | C3: Batch_Number | D3: Units_Produced | E3: Units_Rejected | F3: Rejection_Reason | G3: Unit_Cost_INR | H3: Rework_Cost_INR | I3: Scrap_Cost_INR | J3: Rework_Labour_Hours | K3: Opening_Stock | L3: Sales_Qty | M3: Closing_Stock | N3: Reorder_Qty | O3: Stockout_Incident
A4: Jan-25 | B4: Bone Plate | C4: BOJan25 | D4: 800 | E4: 8 | F4: Surface Finish | G4: 450 | H4: 540 | I4: 288 | J4: 3.2 | K4: 300 | L4: 165 | M4: 927 | N4: 500 | O4: No
A5: Jan-25 | B5: Bone Screw | C5: BOJan25 | D5: 920 | E5: 11 | F5: Thread Defect | G5: 120 | H5: 220 | I5: 110 | J5: 4.4 | K5: 340 | L5: 202 | M5: 1047 | N5: 600 | O5: No
A6: Jan-25 | B6: Intramedullary Nail | C6: INJan25 | D6: 1040 | E6: 16 | F6: Dimension Variation | G6: 950 | H6: 2280 | I6: 1216 | J6: 6.4 | K6: 380 | L6: 239 | M6: 1165 | N6: 700 | O6: No
A7: Jan-25 | B7: Bone Nibbler | C7: BOJan25 | D7: 1160 | E7: 11 | F7: Burr Formation | G7: 2500 | H7: 4125 | I7: 2200 | J7: 4.4 | K7: 420 | L7: 276 | M7: 1293 | N7: 0 | O7: No
A8: Jan-25 | B8: Wire Cutter | C8: WIJan25 | D8: 1280 | E8: 16 | F8: Material Defect | G8: 3000 | H8: 7200 | I8: 3840 | J8: 6.4 | K8: 460 | L8: 313 | M8: 1411 | N8: 0 | O8: No
A9: Jan-25 | B9: Needle Holder | C9: NEJan25 | D9: 1400 | E9: 22 | F9: Packaging Damage | G9: 400 | H9: 1320 | I9: 704 | J9: 8.8 | K9: 500 | L9: 350 | M9: 1528 | N9: 0 | O9: No
A10: Jan-25 | B10: Plaster Cutting Saw | C10: PLJan25 | D10: 1520 | E10: 15 | F10: Surface Finish | G10: 12000 | H10: 27000 | I10: 14400 | J10: 6 | K10: 540 | L10: 387 | M10: 1658 | N10: 0 | O10: No
A11: Feb-25 | B11: Bone Plate | C11: BOFeb25 | D11: 815 | E11: 8 | F11: Thread Defect | G11: 450 | H11: 540 | I11: 288 | J11: 3.2 | K11: 310 | L11: 170 | M11: 947 | N11: 500 | O11: No
A12: Feb-25 | B12: Bone Screw | C12: BOFeb25 | D12: 935 | E12: 12 | F12: Dimension Variation | G12: 120 | H12: 240 | I12: 120 | J12: 4.8 | K12: 350 | L12: 207 | M12: 1066 | N12: 600 | O12: No
A13: Feb-25 | B13: Intramedullary Nail | C13: INFeb25 | D13: 1055 | E13: 16 | F13: Burr Formation | G13: 950 | H13: 2280 | I13: 1216 | J13: 6.4 | K13: 390 | L13: 244 | M13: 1185 | N13: 700 | O13: No
A14: Feb-25 | B14: Bone Nibbler | C14: BOFeb25 | D14: 1175 | E14: 11 | F14: Material Defect | G14: 2500 | H14: 4125 | I14: 2200 | J14: 4.4 | K14: 430 | L14: 281 | M14: 1313 | N14: 0 | O14: No
A15: Feb-25 | B15: Wire Cutter | C15: WIFeb25 | D15: 1295 | E15: 16 | F15: Packaging Damage | G15: 3000 | H15: 7200 | I15: 3840 | J15: 6.4 | K15: 470 | L15: 318 | M15: 1431 | N15: 0 | O15: No
... A122: May-26 | B122: Plaster Cutting Saw | C122: PLMay26 | D122: 1760 | E122: 17 | F122: Material Defect | G122: 12000 | H122: 30600 | I122: 16320 | J122: 6.8 | K122: 700 | L122: 475 | M122: 1968 | N122: 0 | O122: No

Sheet Metadata
A1: Medical Equipment Firm — Metadata | Data Dictionary & Variable Description
A3: SECTION 1 — DATA OVERVIEW
A5: Attribute | B5: Details
A6: Total Records | B6: 119 rows
A7: Time Period | B7: January 2025 to May 2026
A8: Duration | B8: 17 months
A9: Number of Products | B9: 7
A10: Number of Variables | B10: 15
A11: Data Format | B11: Excel (.xlsx)
A12: Missing Values | B12: 0 (complete dataset)
A13: Data Source | B13: Primary — collected directly from KK Surgicals
A14: Data Type | B14: Mixed — Numerical, Categorical, Date
A16: SECTION 2 — VARIABLE DESCRIPTION TABLE
A18: Variable Name | B18: Description | C18: Data Type | D18: Role / Usage | E18: Linked Problem | F18: Source
A19: Month | B19: Month and year of the record | C19: Categorical (Date) | D19: Time dimension for trend analysis | E19: All Problems | F19: Company registers
A20: Product | B20: Name of the product (7 types) | C20: Categorical | D20: Group identifier for product-wise analysis | E20: All Problems | F20: Company records
A21: Batch_Number | B21: Unique batch identifier per product per month | C21: Categorical | D21: Links production batches to quality data | E21: Problem 1 | F21: Production logs
A22: Units_Produced | B22: Total units manufactured in that batch | C22: Numerical (Integer) | D22: Denominator for defect rate calculation | E22: Problem 1 | F22: Production logs
A23: Units_Rejected | B23: Total units rejected/non-conforming | C23: Numerical (Integer) | D23: Numerator for defect rate; SPC input | E23: Problem 1 | F23: Rejection logs
A24: Rejection_Reason | B24: Reason for rejection (6 categories) | C24: Categorical | D24: Pareto & RCA input | E24: Problem 1 | F24: QC inspection records
A25: Unit_Cost_INR | B25: Cost to manufacture one unit (INR) | C25: Numerical (Integer) | D25: COPQ formula input | E25: Problem 2 | F25: Cost sheets
A26: Rework_Cost_INR | B26: Total cost of rework for that batch (INR) | C26: Numerical (Integer) | D26: COPQ component; ANOVA input | E26: Problem 2 | F26: Cost sheets
A27: Scrap_Cost_INR | B27: Total scrap/wastage cost for that batch (INR) | C27: Numerical (Integer) | D27: COPQ component; ANOVA input | E27: Problem 2 | F27: Cost sheets
A28: Rework_Labour_Hours | B28: Labour hours spent on rework for that batch | C28: Numerical (Float) | D28: Labour efficiency analysis | E28: Problem 2 | F28: Production logs
A29: Opening_Stock | B29: Stock available at the start of the month | C29: Numerical (Integer) | D29: Inventory baseline | E29: Problem 3 | F29: Stock registers
... A33: Stockout_Incident | B33: Whether a stockout occurred (Yes/No) | C33: Categorical (Binary) | D33: Stockout frequency; ROP justification | E33: Problem 3 | F33: Stock registers
A35: SECTION 3 — PRODUCTS & REJECTION REASON CATEGORIES
A37: # | B37: Product Name | C37: Unit Cost (INR) | D37: Category | E37: # | F37: Rejection Reason
A38: 1 | B38: Bone Plate | C38: ₹450 | D38: Orthopaedic Implant | E38: 1 | F38: Surface Finish
A39: 2 | B39: Bone Screw | C39: ₹120 | D39: Orthopaedic Implant | E39: 2 | F39: Thread Defect
A40: 3 | B40: Intramedullary Nail | C40: ₹950 | D40: Orthopaedic Implant | E40: 3 | F40: Dimension Variation
A41: 4 | B41: Bone Nibbler | C41: ₹2,500 | D41: Surgical Instrument | E41: 4 | F41: Burr Formation
A42: 5 | B42: Wire Cutter | C42: ₹3,000 | D42: Surgical Instrument | E42: 5 | F42: Material Defect
A43: 6 | B43: Needle Holder | C43: ₹400 | D43: Surgical Instrument | E43: 6 | F43: Packaging Damage
A44: 7 | B44: Plaster Cutting Saw | C44: ₹12,000 | D44: Surgical Instrument

Sheet Descriptive_Statistics
A1: Medical Equipment Firm — Descriptive Statistics | Jan 2025 to May 2026
A3: 4.1 — OVERALL SUMMARY STATISTICS (All Variables)
A5: Variable | B5: Mean | C5: Median | D5: Std Dev | E5: Min | F5: Max | G5: Count | H5: Observation
A6: Units_Produced | B6: =AVERAGE(Raw_Data!D4:D122) -> 1280 | C6: =MEDIAN(Raw_Data!D4:D122) -> 1280 | D6: =STDEV(Raw_Data!D4:D122) -> 252.05932 | E6: =MIN(Raw_Data!D4:D122) -> 800 | F6: =MAX(Raw_Data!D4:D122) -> 1760 | G6: =COUNT(Raw_Data!D4:D122) -> 119 | H6: Units manufactured per batch
A7: Units_Rejected | B7: =AVERAGE(Raw_Data!E4:E122) -> 15.672269 | C7: =MEDIAN(Raw_Data!E4:E122) -> 16 | D7: =STDEV(Raw_Data!E4:E122) -> 4.6634337 | E7: =MIN(Raw_Data!E4:E122) -> 8 | F7: =MAX(Raw_Data!E4:E122) -> 26 | G7: =COUNT(Raw_Data!E4:E122) -> 119 | H7: Units rejected per batch
A8: Defect_Rate (%) | B8: 1.22 | C8: 1.24 | D8: 0.25 | E8: 0.9 | F8: 1.6 | G8: 119 | H8: Percentage of units rejected
A9: Unit_Cost_INR | B9: =AVERAGE(Raw_Data!G4:G122) -> 2774.2857 | C9: =MEDIAN(Raw_Data!G4:G122) -> 950 | D9: =STDEV(Raw_Data!G4:G122) -> 3919.8507 | E9: =MIN(Raw_Data!G4:G122) -> 120 | F9: =MAX(Raw_Data!G4:G122) -> 12000 | G9: =COUNT(Raw_Data!G4:G122) -> 119 | H9: Manufacturing cost per unit (INR)
A10: Rework_Cost_INR | B10: =AVERAGE(Raw_Data!H4:H122) -> 6591.2269 | C10: =MEDIAN(Raw_Data!H4:H122) -> 2565 | D10: =STDEV(Raw_Data!H4:H122) -> 9416.8639 | E10: =MIN(Raw_Data!H4:H122) -> 220 | F10: =MAX(Raw_Data!H4:H122) -> 30600 | G10: =COUNT(Raw_Data!H4:H122) -> 119 | H10: Rework cost per batch (INR)
A11: Scrap_Cost_INR | B11: =AVERAGE(Raw_Data!I4:I122) -> 3514.0672 | C11: =MEDIAN(Raw_Data!I4:I122) -> 1368 | D11: =STDEV(Raw_Data!I4:I122) -> 5023.1773 | E11: =MIN(Raw_Data!I4:I122) -> 110 | F11: =MAX(Raw_Data!I4:I122) -> 16320 | G11: =COUNT(Raw_Data!I4:I122) -> 119 | H11: Scrap cost per batch (INR)
A12: Rework_Labour_Hours | B12: =AVERAGE(Raw_Data!J4:J122) -> 6.2689076 | C12: =MEDIAN(Raw_Data!J4:J122) -> 6.4 | D12: =STDEV(Raw_Data!J4:J122) -> 1.8653735 | E12: =MIN(Raw_Data!J4:J122) -> 3.2 | F12: =MAX(Raw_Data!J4:J122) -> 10.4 | G12: =COUNT(Raw_Data!J4:J122) -> 119 | H12: Labour hours on rework per batch
A13: Opening_Stock | B13: =AVERAGE(Raw_Data!K4:K122) -> 500 | C13: =MEDIAN(Raw_Data!K4:K122) -> 500 | D13: =STDEV(Raw_Data!K4:K122) -> 94.204969 | E13: =MIN(Raw_Data!K4:K122) -> 300 | F13: =MAX(Raw_Data!K4:K122) -> 700 | G13: =COUNT(Raw_Data!K4:K122) -> 119 | H13: Stock at start of month
A14: Sales_Qty | B14: =AVERAGE(Raw_Data!L4:L122) -> 319.76471 | C14: =MEDIAN(Raw_Data!L4:L122) -> 320 | D14: =STDEV(Raw_Data!L4:L122) -> 79.086169 | E14: =MIN(Raw_Data!L4:L122) -> 165 | F14: =MAX(Raw_Data!L4:L122) -> 475 | G14: =COUNT(Raw_Data!L4:L122) -> 119 | H14: Units sold per month
A15: Closing_Stock | B15: =AVERAGE(Raw_Data!M4:M122) -> 1444.563 | C15: =MEDIAN(Raw_Data!M4:M122) -> 1448 | D15: =STDEV(Raw_Data!M4:M122) -> 261.82585 | E15: =MIN(Raw_Data!M4:M122) -> 927 | F15: =MAX(Raw_Data!M4:M122) -> 1968 | G15: =COUNT(Raw_Data!M4:M122) -> 119 | H15: Stock at end of month
A16: COPQ (INR) | B16: 10105.29 | C16: 3933 | D16: 14440.04 | E16: 330 | F16: 46920 | G16: 119 | H16: Total Cost of Poor Quality per batch
A18: 4.2 — PRODUCT-WISE DEFECT RATE
A20: Product | B20: Total Produced | C20: Total Rejected | D20: Defect Rate (%) | E20: Rank | F20: Status
A21: Bone Plate | B21: 15640 | C21: 149 | D21: 0.95 | E21: 1 | F21: BELOW AVERAGE
A22: Bone Nibbler | B22: 21760 | C22: 209 | D22: 0.96 | E22: 2 | F22: BELOW AVERAGE
A23: Plaster Cutting Saw | B23: 27880 | C23: 271 | D23: 0.97 | E23: 3 | F23: BELOW AVERAGE
A24: Bone Screw | B24: 17680 | C24: 221 | D24: 1.25 | E24: 4 | F24: ABOVE AVERAGE
A25: Wire Cutter | B25: 23800 | C25: 301 | D25: 1.26 | E25: 5 | F25: ABOVE AVERAGE
A26: Intramedullary Nail | B26: 19720 | C26: 308 | D26: 1.56 | E26: 6 | F26: ABOVE AVERAGE
A27: Needle Holder | B27: 25840 | C27: 406 | D27: 1.57 | E27: 7 | F27: ABOVE AVERAGE
A30: 4.3 — PRODUCT-WISE COST OF POOR QUALITY (COPQ)
A32: Product | B32: Rework Cost (INR) | C32: Scrap Cost (INR) | D32: Total COPQ (INR) | E32: COPQ % of Total | F32: Labour Hours
A33: Bone Screw | B33: 4420 | C33: 2210 | D33: 6630 | E33: 0.55% | F33: 88.4
A34: Bone Plate | B34: 10061 | C34: 5364 | D34: 15425 | E34: 1.28% | F34: 59.6
A35: Needle Holder | B35: 24360 | C35: 12992 | D35: 37352 | E35: 3.11% | F35: 162.4
A36: Intramedullary Nail | B36: 43890 | C36: 23408 | D36: 67298 | E36: 5.6% | F36: 123.2
A37: Bone Nibbler | B37: 78375 | C37: 41800 | D37: 120175 | E37: 9.99% | F37: 83.6
A38: Wire Cutter | B38: 135450 | C38: 72240 | D38: 207690 | E38: 17.27% | F38: 120.4
A39: Plaster Cutting Saw | B39: 487800 | C39: 260160 | D39: 747960 | E39: 62.2% | F39: 108.4
A40: TOTAL | B40: 784356 | C40: 418174 | D40: 1202530 | E40: 100% | F40: 746
A42: 4.4 — INVENTORY SUMMARY BY PRODUCT
A44: Product | B44: Avg Opening Stock | C44: Avg Sales/Month | D44: Avg Closing Stock | E44: Min Closing Stock | F44: Stockout Incidents
A45: Bone Nibbler | B45: 500 | C45: 320 | D45: 1448 | E45: 1293 | F45: 0
A46: Bone Plate | B46: 380 | C46: 209 | D46: 1082 | E46: 927 | F46: 1
A47: Bone Screw | B47: 420 | C47: 246 | D47: 1201 | E47: 1047 | F47: 1
A48: Intramedullary Nail | B48: 460 | C48: 283 | D48: 1319 | E48: 1165 | F48: 0
A49: Needle Holder | B49: 580 | C49: 394 | D49: 1682 | E49: 1528 | F49: 0
...

Sheet P1_Defect_Analysis
A1: Medical Equipment Firm — Problem 1: Defect Rate Analysis | Jan 2025 to May 2026
A2: Methods: Root Cause Analysis (RCA) + Statistical Process Control (SPC) · Tools: Excel + Python
A4: TABLE 1 — MONTHLY DEFECT RATE TREND
A6: Month | B6: Total Produced | C6: Total Rejected | D6: Defect Rate (%) | E6: vs Previous Month | F6: Trend
A7: Jan-25 | B7: 8120 | C7: 99 | D7: 1.22 | E7: — | F7: —
A8: Feb-25 | B8: 8225 | C8: 100 | D8: 1.22 | E8: +0.00% | F8: Decreasing
A9: Mar-25 | B9: 8330 | C9: 102 | D9: 1.22 | E9: +0.00% | F9: Decreasing
A10: Apr-25 | B10: 8435 | C10: 104 | D10: 1.23 | E10: +0.01% | F10: Increasing
A11: May-25 | B11: 8540 | C11: 104 | D11: 1.22 | E11: -0.01% | F11: Decreasing
A12: Jun-25 | B12: 8645 | C12: 104 | D12: 1.2 | E12: -0.02% | F12: Decreasing
A13: Jul-25 | B13: 8750 | C13: 107 | D13: 1.22 | E13: +0.02% | F13: Increasing
A14: Aug-25 | B14: 8855 | C14: 110 | D14: 1.24 | E14: +0.02% | F14: Increasing
A15: Sep-25 | B15: 8960 | C15: 110 | D15: 1.23 | E15: -0.01% | F15: Decreasing
A16: Oct-25 | B16: 9065 | C16: 110 | D16: 1.21 | E16: -0.02% | F16: Decreasing
A17: Nov-25 | B17: 9170 | C17: 112 | D17: 1.22 | E17: +0.01% | F17: Increasing
A18: Dec-25 | B18: 9275 | C18: 114 | D18: 1.23 | E18: +0.01% | F18: Increasing
... A24: OVERALL | B24: 152320 | C24: 1865 | D24: 1.22 | E24: — | F24: Upward Trend
A26: TABLE 2 — REJECTION REASON FREQUENCY (Pareto Analysis)
A28: Rejection Reason | B28: Frequency | C28: % of Total | D28: Cumulative % | E28: Pareto Rank | F28: Action Priority
A29: Surface Finish | B29: 20 | C29: 16.81% | D29: 16.81% | E29: 1 | F29: HIGH
A30: Thread Defect | B30: 20 | C30: 16.81% | D30: 33.62% | E30: 2 | F30: HIGH
A31: Dimension Variation | B31: 20 | C31: 16.81% | D31: 50.43% | E31: 3 | F31: HIGH
A32: Burr Formation | B32: 20 | C32: 16.81% | D32: 67.24% | E32: 4 | F32: HIGH
A33: Material Defect | B33: 20 | C33: 16.81% | D33: 84.05% | E33: 5 | F33: MEDIUM
A34: Packaging Damage | B34: 19 | C34: 15.97% | D34: 100.02% | E34: 6 | F34: MEDIUM

Sheet P2_COPQ_Analysis
A1: Medical Equipment Firm — Problem 2: Cost of Poor Quality (COPQ) Analysis | Jan 2025 to May 2026
A2: Methods: COPQ Formula + Hypothesis Testing (T-test, ANOVA) · Tools: Excel + Python (SciPy, statsmodels)
A4: COPQ FORMULA: COPQ = (Unit Cost × Non-Conforming Qty) + Rework Cost + Scrap Cost
A6: TABLE 1 — MONTHLY COPQ TREND
A8: Month | B8: Rework Cost (INR) | C8: Scrap Cost (INR) | D8: Total COPQ (INR) | E8: Labour Hours | F8: MoM Change | G8: Trend
A9: Jan-25 | B9: 42685 | C9: 22758 | D9: 65443 | E9: 39.6 | F9: — | G9: —
A10: Feb-25 | B10: 42705 | C10: 22768 | D10: 65473 | E10: 40 | F10: ₹+30 | G10: ▲
A11: Mar-25 | B11: 43297 | C11: 23084 | D11: 66381 | E11: 40.8 | F11: ₹+908 | G11: ▲
A12: Apr-25 | B12: 43732 | C12: 23316 | D12: 67048 | E12: 41.6 | F12: ₹+667 | G12: ▲
A13: May-25 | B13: 43732 | C13: 23316 | D13: 67048 | E13: 41.6 | F13: ₹+0 | G13: ▼
A14: Jun-25 | B14: 43732 | C14: 23316 | D14: 67048 | E14: 41.6 | F14: ₹+0 | G14: ▼
A15: Jul-25 | B15: 45695 | C15: 24362 | D15: 70057 | E15: 42.8 | F15: ₹+3,009 | G15: ▲
A16: Aug-25 | B16: 46273 | C16: 24670 | D16: 70943 | E16: 44 | F16: ₹+886 | G16: ▲
A17: Sep-25 | B17: 46273 | C17: 24670 | D17: 70943 | E17: 44 | F17: ₹+0 | G17: ▼
A18: Oct-25 | B18: 46273 | C18: 24670 | D18: 70943 | E18: 44 | F18: ₹+0 | G18: ▼
A19: Nov-25 | B19: 46791 | C19: 24946 | D19: 71737 | E19: 44.8 | F19: ₹+794 | G19: ▲
A20: Dec-25 | B20: 46871 | C20: 24988 | D20: 71859 | E20: 45.6 | F20: ₹+122 | G20: ▲
... A26: TOTAL | B26: 784356 | C26: 418174 | D26: 1202530 | E26: 746 | F26: — | G26: RISING ▲
A28: TABLE 2 — PRODUCT-WISE COPQ BREAKDOWN
A30: Product | B30: Rework Cost (INR) | C30: Scrap Cost (INR) | D30: Total COPQ (INR) | E30: % of Total COPQ | F30: Labour Hours | G30: Priority
A31: Bone Screw | B31: 4420 | C31: 2210 | D31: 6630 | E31: 0.55% | F31: 88.4 | G31: MEDIUM
A32: Bone Plate | B32: 10061 | C32: 5364 | D32: 15425 | E32: 1.28% | F32: 59.6 | G32: MEDIUM
A33: Needle Holder | B33: 24360 | C33: 12992 | D33: 37352 | E33: 3.11% | F33: 162.4 | G33: MEDIUM
A34: Intramedullary Nail | B34: 43890 | C34: 23408 | D34: 67298 | E34: 5.6% | F34: 123.2 | G34: MEDIUM
A35: Bone Nibbler | B35: 78375 | C35: 41800 | D35: 120175 | E35: 9.99% | F35: 83.6 | G35: MEDIUM
A36: Wire Cutter | B36: 135450 | C36: 72240 | D36: 207690 | E36: 17.27% | F36: 120.4 | G36: HIGH
A37: Plaster Cutting Saw | B37: 487800 | C37: 260160 | D37: 747960 | E37: 62.2% | F37: 108.4 | G37: CRITICAL

Sheet P3_Inventory_Analysis
A1: Medical Equipment Firm — Problem 3: Inventory Analysis | Jan 2025 to May 2026
A2: Methods: ABC Classification + EOQ + ROP + Safety Stock + ARIMA · Tools: Excel + Python
A4: TABLE 1 — MONTHLY SALES TREND BY PRODUCT
A6: Month | B6: Bone Plate | C6: Bone Screw | D6: Intramedullary Nail | E6: Bone Nibbler | F6: Wire Cutter | G6: Needle Holder | H6: Plaster Cutting Saw | I6: Total Sales
A7: Jan-25 | B7: 165 | C7: 202 | D7: 239 | E7: 276 | F7: 313 | G7: 350 | H7: 387 | I7: 1932
A8: Feb-25 | B8: 170 | C8: 207 | D8: 244 | E8: 281 | F8: 318 | G8: 355 | H8: 392 | I8: 1967
A9: Mar-25 | B9: 176 | C9: 213 | D9: 250 | E9: 287 | F9: 324 | G9: 361 | H9: 398 | I9: 2009
A10: Apr-25 | B10: 181 | C10: 218 | D10: 255 | E10: 292 | F10: 329 | G10: 366 | H10: 403 | I10: 2044
A11: May-25 | B11: 187 | C11: 224 | D11: 261 | E11: 298 | F11: 335 | G11: 372 | H11: 409 | I11: 2086
A12: Jun-25 | B12: 192 | C12: 229 | D12: 266 | E12: 303 | F12: 340 | G12: 377 | H12: 414 | I12: 2121
A13: Jul-25 | B13: 198 | C13: 235 | D13: 272 | E13: 309 | F13: 346 | G13: 383 | H13: 420 | I13: 2163
A14: Aug-25 | B14: 203 | C14: 240 | D14: 277 | E14: 314 | F14: 351 | G14: 388 | H14: 425 | I14: 2198
A15: Sep-25 | B15: 209 | C15: 246 | D15: 283 | E15: 320 | F15: 357 | G15: 394 | H15: 431 | I15: 2240
A16: Oct-25 | B16: 214 | C16: 251 | D16: 288 | E16: 325 | F16: 362 | G16: 399 | H16: 436 | I16: 2275
A17: Nov-25 | B17: 220 | C17: 257 | D17: 294 | E17: 331 | F17: 368 | G17: 405 | H17: 442 | I17: 2317
A18: Dec-25 | B18: 225 | C18: 262 | D18: 299 | E18: 336 | F18: 373 | G18: 410 | H18: 447 | I18: 2352
... A24: TOTAL | B24: 3549 | C24: 4178 | D24: 4807 | E24: 5436 | F24: 6065 | G24: 6694 | H24: 7323 | I24: 38052
A26: TABLE 2 — ABC INVENTORY CLASSIFICATION
A28: Product | B28: Unit Cost (INR) | C28: Avg Monthly Sales | D28: Annual Demand (est.) | E28: Annual Value (INR) | F28: % Cumulative Value | G28: ABC Class | H28: Management Priority
A29: Plaster Cutting Saw | B29: ₹12,000 | C29: 431 | D29: 5172 | E29: ₹62,064,000 | F29: 68.12% | G29: A | H29: HIGH — Monitor closely
A30: Wire Cutter | B30: ₹3,000 | C30: 357 | D30: 4284 | E30: ₹12,852,000 | F30: 82.22% | G30: B | H30: MEDIUM — Regular review
A31: Bone Nibbler | B31: ₹2,500 | C31: 320 | D31: 3840 | E31: ₹9,600,000 | F31: 92.76% | G31: C | H31: LOW — Simplified control
A32: Intramedullary Nail | B32: ₹950 | C32: 283 | D32: 3396 | E32: ₹3,226,200 | F32: 96.3% | G32: C | H32: LOW — Simplified control
A33: Needle Holder | B33: ₹400 | C33: 394 | D33: 4728 | E33: ₹1,891,200 | F33: 98.37% | G33: C | H33: LOW — Simplified control
A34: Bone Plate | B34: ₹450 | C34: 209 | D34: 2508 | E34: ₹1,128,600 | F34: 99.61% | G34: C | H34: LOW — Simplified control
A35: Bone Screw | B35: ₹120 | C35: 246 | D35: 2952 | E35: ₹354,240 | F35: 100.0% | G35: C | H35: LOW — Simplified control
A38: TABLE 3 — STOCKOUT INCIDENTS SUMMARY
A40: Month | B40: Product | C40: Sales Qty | D40: Closing Stock | E40: Stockout | F40: Action Required
A41: Jul-25 | B41: Bone Screw | C41: 235 | D41: 1162 | E41: Yes | F41: Implement ROP & Safety Stock
A42: Feb-26 | B42: Bone Plate | C42: 236 | D42: 1180 | E42: Yes | F42: Implement ROP & Safety Stock
